Workbook
Name Hours.WorkWeek: Hours!$K$2:$K$2
Name Monthly.CU.Hours: 'Cloud Expenses'!$U$2:$U$2
Name Weeks.Month: Hours!$D$2:$D$2

Sheet Sheet1
A1: Item | B1: Brand | C1: Model | D1: UPC # | E1: Quanity | F1: Pack Size | G1: Cost per Item Pack | H1: Shipping Cost | I1: Sales Tax Rate | J1: Line Item Subtotal w/ EC102NU2M | K1: Line Item Subtotal EC308-Li | L1: Vendor | M1: Use Case | N1: Specs | O1: Cons
A2: Label Printer | B2: Dymo | C2: Label Writer 5XL Label Printer | D2: 71701062505 | E2: 2 | F2: 1 | G2: 199.8 | L2: Office Depot | M2: Prints Labels- one for mobile workstation & other for stationary desk @ control desk | N2: Specs | O2: Required Propritary Branded Labels
A3: Label Printer | B3: Brother | C3: Brother QL-1100 Label Printer | D3: 12502648932 | E3: 2 | F3: 1 | G3: 229.99 | H3: 0 | I3: 1.08 | J3: =(E3*G3*I3)+H3 | L3: Staples | M3: Prints Labels- one for mobile workstation & other for stationary desk @ control desk | N3: specs
A4: DK1202 White Die-Cut Direct Thermal Labels. Label Size: 2-3/7" x 4" (62mm x 100mm). 300 Labels/Roll, 12 Rolls/Box, Total 3,600 Labels with 1 Reusable Cartridge Frame | B4: StickerTag | C4: DK1202 | E4: 13 | F4: 1 | G4: 36.99 | H4: 0 | I4: =I3 | J4: =(E4*G4*I4)+H4 | L4: Amazon | M4: Thermal labels for labeling inventory, locations, & printing pack slips. | N4: Color White Size 2.4" x 3.9" - DK1202 Material Paper Brand StickerTag Finish Type Adhesive | P4: 3 users / 2 labels per item / 2 possible labels per process / 18 cases per day per user / 4 days per week | Q4: =3*2*2*18*4*52 | R4: =Q4/3600 | S4: Around [ 13 ] - 12 pack cases of 3600 each pack of labels per year, estimating around 45,000 labels needed per year
A5: Computer Rolling Cart | B5: New Castle Systems | C5: EC102NU2M | D5: Reference #: 20260904-111210232 | E5: 2 | F5: 1 | G5: 3437 | I5: =I4 | J5: =(E5*G5*I5)+H5 | L5: New Castle Systems | M5: Mobile Workstation for labeling, shipping, recieving, inventory control, & cycle counting. | N5: Compact powered cart, PowerSwap Nucleus® MINI lithium system w/(2) 230 Wh swappable batteries & charging station
A6: Computer Rolling Cart | B6: New Castle Systems | C6: EC308-LI | D6: Reference #: 20260904-110942161 | E6: 2 | F6: 1 | G6: 3273 | I6: =I5 | K6: =(E6*G6*I6)+H6 | L6: New Castle Systems | M6: Mobile Workstation for labeling, shipping, recieving, inventory control, & cycle counting. | N6: Fixed Lithium / SLA (EC380 / EC380-LI) — 1,200–1,280 Wh, 450W continuous output. Powers a laptop, LCD monitor, and mid-range thermal printer for a full shift.
A7: Middle Shelf | B7: New Castle Systems | C7: B423 | D7: Reference #: 20260904-111210232 | E7: 2 | F7: 1 | G7: 107 | I7: =I6 | J7: =(E7*G7*I7)+H7 | L7: New Castle Systems | M7: Center shelf accessory for storing thermal printer, labels, markers, tape, & other minor materials for shipping & recieving.
A8: Scanner Holder | B8: New Castle Systems | C8: B132 | D8: Reference #: 20260904-111210232 | E8: 2 | F8: 1 | G8: 46 | I8: =I7 | J8: =(E8*G8*I8)+H8 | L8: New Castle Systems | M8: User friendly & ergonomic scanner holder for hands free scanning & docking of scanning device. Makes for a dedicated station for quick easy access to scanning technologies.
A9: Laptop / tablet holder w/7" arm (adjustable 10"-17" wide) (12 x 10 x 6" | B9: New Castle Systems | C9: B112 | D9: Reference #: 20260904-111210232 | E9: 2 | F9: 1 | G9: 213 | I9: =I8 | J9: =(E9*G9*I9)+H9 | L9: New Castle Systems | M9: An accessory to the computer rolling cart to secure the device in a mounted armature. This will provide integrity to company electronics while also freeing up space on the mobile work station.
A10: Tera - 1D 2D Wireless Barcode Scanner with LED Screen and Charging Cradle HW0006 | B10: Tera | C10: HW0006 | D10: ="192531066157" | E10: 2 | F10: 1 | G10: 36.87 | I10: =I9 | J10: =(E10*G10*I10)+H10 | L10: Best Buy | M10: Wireless Scan Barcodes for inventory | O10: Must Charge; 13 hour operating time.
A11: Packing Tape with Acrylic Adhesive | CST20WBA (110 yd, 2.0 Mil) | B11: TapeProviders | C11: TP-CSTWBA-PA | D11: TP CST20WBA-03000-24-110-CLE | E11: =ROUND((65/F11),0) | F11: 36 | G11: 46.26 | I11: =I10 | J11: =(E11*G11*I11)+H11 | L11: TapeProviders | M11: Tape used for sealing produts in packaging. | N11: 36 / box ; 3 " wide ; 2 mil thick | P11: 6 users == 1.25 rolls / week | Q11: =1.25*52 | R11: Around 65 Rolls Tape a year
A12: Silent Packing Tape Dispenser - General Grade | CSTD-LN Max Width 3" | B12: TapeProviders | C12: CSTD3LN | D12: WOD CSTD3LN-1 | E12: 9 | F12: 1 | G12: 16.85 | I12: =I11 | J12: =(E12*G12*I12)+H12 | L12: TapeProviders | M12: Professional and ergonomic tape dispensor tool used for shipping, recieving, and inventory repacking. | P12: 4 users == 2.25 reels / 12 months | Q12: =4*2.25*1 | R12: Around 9 Tape Reels a Year
A13: 100 Pack Permanent Markers Bulk Black Set Fine Point Marker Pens Waterproof Works On Plastic Wood Stone Metal And Glass | B13: Unbranded | C13: ="835645224524" | E13: =ROUND((156/F13),0) | F13: 100 | G13: 42.48 | H13: 0 | I13: =I12 | J13: =(E13*G13*I13)+H13 | L13: Walmart | M13: User to mark pallets, product, and inventorey | P13: 6 users / 1.5 markers / 3 weeks | Q13: =6*1.5*(52/3) | R13: Around 156 markers a year
A14: Brother DS-640 Compact Mobile Document Scanner, (Model: DS640) | B14: Brother | C14: DS640 | D14: Part #: 78152934 | E14: 2 | F14: 1 | G14: 134.99 | I14: =I16 | J14: =(E14*G14*I14)+H14
A15: Klevor Koncept Safety Knife | B15: Klevor Koncept | C15: SC KK-201 | E15: 105 | F15: 1 | G15: 1.79 | I15: =I14 | J15: =(E15*G15*I15)+H15 | P15: 6 users / 1 blade / 3 weeks | Q15: =6*(52/3) | R15: Around 104 Safety Blades a year
A16: Carboard Boxes | I16: =I13 | J16: =(E16*G16*I16)+H16
J17: =SUM(J2:J16) | K17: =SUM(J2:J4)+SUM(J7:J16)+K6
C19: Pricing Options | D19: Plan | E19: Estimated Monthly Cost | F19: RAM / Specs | G19: Storage GB | H19: HA / Redundancy | I19: Notes | L19: Current Plan in Development | M19: Current Plan Cost While in Development / Month
A20: Optional serverless Postgres (skip if using Heroku Postgres) | B20: Neon | C20: Neon Pricing | D20: Launch — Usage Based | E20: 22 | I20: Not needed once Heroku Postgres is the system of record. | L20: Free | M20: 0
A21: No need to use — redundant with Heroku hosting frontend + backend | B21: Netlify | C21: Netlify Pricing | L21: Free | M21: 0
A22: Heroku Dynos — Saltbox Next.js app compute | B22: Heroku | C22: Heroku Dynos Pricing
A23: Eco (dev only — sleeps after 30 min) | B23: Heroku | C23: Heroku Dynos Pricing | D23: Eco | E23: 5 | F23: 0.5 GB | G23: — | H23: Sleeps | I23: Development only | L23: Cedar - Eco Dyno | M23: 5
A24: Basic (always-on entry) | B24: Heroku | C24: Heroku Dynos Pricing | D24: Basic | E24: 7 | F24: 0.5 GB | G24: — | H24: Limited | I24: Always-on; limited prod features
A25: Standard-1X (RECOMMENDED production web) | B25: Heroku | C25: Heroku Dynos Pricing | D25: Standard-1X | E25: 25 | F25: 0.5 GB | G25: — | H25: Metrics + preboot | I25: Recommended prod dyno; free ACM SSL
A26: Standard-2X (scale-up if OOM) | B26: Heroku | C26: Heroku Dynos Pricing | D26: Standard-2X | E26: 50 | F26: 1 GB | G26: — | H26: Metrics + preboot | I26: Only if Standard-1X runs out of memory
A27: Performance-M (overkill comparison) | B27: Heroku | C27: Heroku Dynos Pricing | D27: Performance-M | E27: 250 | F27: 2.5 GB dedicated | G27: — | H27: Dedicated | I27: Not recommended for Saltbox ATL scale | L27: Cedar Private - Medium (ref) | M27: 250
A28: Heroku Postgres — managed DATABASE_URL store | B28: Heroku | C28: Heroku Data Services Pricing
A29: Essential-0 (dev) | B29: Heroku | C29: Heroku Data Services Pricing | D29: Essential-0 | E29: 5 | F29: Shared | G29: 1 | H29: No HA | I29: Dev/staging only | L29: Essential-0 | M29: 5
A30: Essential-1 | B30: Heroku | C30: Heroku Data Services Pricing | D30: Essential-1 | E30: 9 | F30: Shared | G30: 10 | H30: No HA | I30: Dev with more storage
A31: Essential-2 | B31: Heroku | C31: Heroku Data Services Pricing | D31: Essential-2 | E31: 20 | F31: Shared | G31: 32 | H31: No HA | I31: Still no redundancy for prod goals
A32: Standard-0 (lean prod) | B32: Heroku | C32: Heroku Data Services Pricing | D32: Standard-0 | E32: 50 | F32: 4 GB RAM | G32: 64 | H32: Forks; no auto HA | I32: Lean prod — up to ~1 hr downtime/mo
A33: Premium-0 (RECOMMENDED — HA) | B33: Heroku | C33: Heroku Data Services Pricing | D33: Premium-0 | E33: 200 | F33: 4 GB RAM | G33: 64 | H33: Automatic HA failover | I33: Matches security/connectivity/redundancy goals
A34: Heroku Add-ons
A35: Bucketeer S3 for photos (required in prod) | B35: Bucketeer | C35: Heroku Add-ons Pricing | D35: Hobbyist | E35: 5 | F35: S3 | G35: — | H35: Durable storage | I35: Ephemeral dyno disk cannot keep data/photos/
A36: ACM SSL (included) | B36: Heroku | C36: Heroku Add-ons Pricing | D36: ACM SSL | E36: 0 | F36: — | G36: — | H36: TLS | I36: Free with paid dynos
A37: Papertrail logs (optional free tier) | B37: Papertrail | C37: Heroku Add-ons Pricing | D37: Choklad | E37: 0 | F37: — | G37: — | H37: Logging | I37: Upgrade later if needed
A38: Redis — NOT required (cookie sessions) | B38: Heroku KVS | C38: Heroku Add-ons Pricing | D38: Not provisioned | E38: 0 | F38: — | G38: — | H38: N/A | I38: Skip unless architecture changes
A39: AI code editor (tooling, not runtime) | B39: Cursor | C39: Cursor Plan Pricing | D39: Pro (current) | E39: 60 | I39: Separate from Heroku cloud runtime costs. | L39: Pro | M39: 60
A41: MONTHLY COST TOTALS (Heroku) | D41: Scenario | E41: Total Cost | I41: Stack
D42: Development Monthly | E42: =E23+E29 | I42: Eco + Essential-0
...

Sheet Cloud Expenses
C1: Pricing Options | D1: Plan | E1: Estimated Monthly Plan Cost | F1: Estimated Usage Cost | G1: RAM / Specs | H1: Storage GB Included | I1: Connections | J1: HA / Redundancy | K1: Max Downtime / Month | L1: Notes / Why | M1: Include in Recommended Prod? | N1: Include in Lean Prod? | O1: Include in Dev? | P1: Annual Cost (Recommended if flagged) | Q1: Estimated Database Storage Cost / Month | R1: Estimated Active Capacity Hours per month | S1: Estimated Compute Hours / day | T1: Compute Hours / work week | U1: Estimated Compute Hours / Month | V1: Estimated coster per CU-Hour (@ 4gb ram) | W1: Estimated Compute Hours Cost per Month | X1: Current Plan in Development | Y1: Estimated Current Plan Cost While in Development / Month
A2: fully managed, serverless PostgreSQL database platform designed for modern cloud-native applications and AI workflows | B2: Neon | C2: Neon Pricing | D2: Launch- Usage Based - Low Load, 5 GB | E2: 22 | G2: 12 | H2: 0.35 | I2: =G2*H2 | J2: 0.09 | K2: =G2*J2 | L2: Optional alternative to Heroku Postgres. Skip once Heroku Postgres is system of record. | M2: No | N2: No | O2: No (use Heroku Essential-0 instead) | P2: 0.2 | Q2: =O2*P2 | R2: 10 | S2: 3 | T2: =S2*6 | U2: {=T2*Weeks.Month} | V2: 0.106 | W2: =U2*V2 | X2: Free | Y2: 0 | Z2: For a single compute, the calculation works similar to this: | AA2: Monthly CU-hours = [average CU size] × [number of hours the compute runs in the month] | AB2: Monthly compute cost = [monthly CU-hours] × [CU-hour price] | AC2: Object Storage is $0.023 per GB-month of stored volume. There's no per-operation charge. Egress counts toward your public network transfer allowance. The Free plan includes 5 GB of Object Storage per project. | AD2: Functions are billed for active compute, waiting compute, and invocations at the rates in the plan table. The Free plan includes 10 active capacity-hours, 400 waiting capacity-hours, and 1 million invocations per month. | AE2: AI Gateway is available on Launch and Scale. Pricing matches the model provider's list prices, with no markup, and draws down prepaid credits. Learn how prepaid credits work, or see per-model rates
A3: No need to use! Redundant use case due to heroku handeling front end and backend | B3: Netlify | C3: Netlify Pricing | L3: Redundant — Heroku hosts frontend + backend. | M3: No | N3: No | O3: No | X3: Free | Y3: 0
A4: Heroku Dynos — app compute (Next.js web process) | C4: Heroku Dynos Pricing
A5: cloud-based PaaS dyno for running the Saltbox Next.js app | B5: Heroku | C5: Heroku Dynos Pricing | D5: Eco | E5: 5 | G5: 0.5 GB | H5: — | I5: — | J5: No (sleeps) | K5: Sleeps after 30 min idle | L5: Dev only. Not for warehouse production — cold starts break connectivity. | M5: No | N5: No | O5: Yes | X5: Cedar - Eco Dyno | Y5: 5
A6: Always-on entry dyno | B6: Heroku | C6: Heroku Dynos Pricing | D6: Basic | E6: 7 | G6: 0.5 GB | H6: — | I6: — | J6: No metrics / limited | K6: Always on | L6: Always-on but lacks production metrics and zero-downtime deploys. | M6: No | N6: No | O6: No
A7: Production web dyno (recommended) | B7: Heroku | C7: Heroku Dynos Pricing | D7: Standard-1X | E7: 25 | G7: 0.5 GB | H7: — | I7: — | J7: Metrics + preboot | K7: Always on | L7: Recommended production dyno: metrics, zero-downtime deploys, free ACM SSL, enough for Saltbox ATL concurrent users. | M7: Yes | N7: Yes | O7: No
A8: Larger production dyno if memory pressure | B8: Heroku | C8: Heroku Dynos Pricing | D8: Standard-2X | E8: 50 | G8: 1 GB | H8: — | I8: — | J8: Metrics + preboot | K8: Always on | L8: Scale-up option if Next.js OOMs on Standard-1X. Not needed at launch. | M8: No | N8: No | O8: No
A9: Dedicated high-performance dyno | B9: Heroku | C9: Heroku Dynos Pricing | D9: Performance-M | E9: 250 | G9: 2.5 GB dedicated | H9: — | I9: — | J9: Dedicated CPU | K9: Always on | L9: Overkill for Saltbox ATL warehouse inventory scale. Kept for pricing comparison only. | M9: No | N9: No | O9: No | X9: Cedar Private - Medium (ref) | Y9: 250
A10: Heroku Postgres — managed PostgreSQL (DATABASE_URL) | C10: Heroku Data Services Pricing
A11: Shared starter Postgres for development | B11: Heroku | C11: Heroku Data Services Pricing | D11: Essential-0 | E11: 5 | G11: Shared | H11: 1 | I11: 20 | J11: No | K11: ~4 hours | L11: Dev/staging only. Encryption at rest. No fork/follow/HA. | M11: No | N11: No | O11: Yes | X11: Essential-0 | Y11: 5
A12: Shared Postgres more storage | B12: Heroku | C12: Heroku Data Services Pricing | D12: Essential-1 | E12: 9 | G12: Shared | H12: 10 | I12: 20 | J12: No | K12: ~4 hours | L12: Dev with more storage headroom. | M12: No | N12: No | O12: No
A13: Shared Postgres largest Essential | B13: Heroku | C13: Heroku Data Services Pricing | D13: Essential-2 | E13: 20 | G13: Shared | H13: 32 | I13: 40 | J13: No | K13: ~4 hours | L13: Still no HA — not for production redundancy goals. | M13: No | N13: No | O13: No
A14: Dedicated Postgres lean production | B14: Heroku | C14: Heroku Data Services Pricing | D14: Standard-0 | E14: 50 | G14: 4 GB RAM | H14: 64 | I14: 200 | J14: Forks/followers; no auto HA | K14: ~1 hour | L14: Lean production: continuous protection, 4-day rollback, forks. No automatic failover. | M14: No | N14: Yes | O14: No
A15: Dedicated Postgres with High Availability (recommended) | B15: Heroku | C15: Heroku Data Services Pricing | D15: Premium-0 | E15: 200 | G15: 4 GB RAM | H15: 64 | I15: 200 | J15: Yes — automatic HA failover | K15: ~15 minutes | L15: RECOMMENDED for security/connectivity/redundancy: HA standby, 7-day rollback, forks/followers, encryption at rest. | M15: Yes | N15: No | O15: No
A16: Heroku Add-ons — storage, TLS, logging | C16: Heroku Add-ons Pricing
A17: S3 object storage for inventory/shipping photos (data/photos cannot live on ephemeral dyno disk) | B17: Bucketeer | C17: Heroku Add-ons Pricing | D17: Hobbyist | E17: 5 | G17: S3 bucket | H17: — | I17: — | J17: Durable object storage | K17: — | L17: Required for production photo persistence on Heroku. | M17: Yes | N17: Yes | O17: Optional
A18: Automated Certificate Management — free TLS for custom domains | B18: Heroku ACM SSL | C18: Heroku Add-ons Pricing | D18: Included with paid dynos | E18: 0 | G18: — | H18: — | I18: — | J18: TLS encryption in transit | K18: — | L18: Included at $0 with Basic/Standard/Performance dynos. | M18: Yes | N18: Yes | O18: Yes (with paid dyno)
A19: Optional log drain for ops visibility | B19: Papertrail | C19: Heroku Add-ons Pricing | D19: Choklad (free tier) | E19: 0 | G19: — | H19: — | I19: — | J19: Log retention | K19: — | L19: Start free; upgrade later if log volume grows (~$7+). | M19: No | N19: No | O19: Optional
A20: Redis/Key-Value Store — NOT required (app uses httpOnly cookie sessions) | B20: Heroku Key-Value Store | C20: Heroku Add-ons Pricing | D20: Mini (not needed) | E20: 0 | G20: — | H20: — | I20: — | J20: N/A | K20: — | L20: Do not provision unless session/cache architecture changes. Mini would be $3/mo if ever needed. | M20: No | N20: No | O20: No
A21: AI-powered code editor / development platform | B21: Cursor | C21: Cursor Plan Pricing | D21: Individual | E21: 20 | L21: Developer tooling — not a Heroku runtime cost. | M21: No | N21: No | O21: No | X21: Pro | Y21: 60
C22: Cursor Plan Pricing | D22: Teams | E22: 40 | M22: No | N22: No | O22: No
A24: MONTHLY COST TOTALS (Heroku Saltbox ATL) | D24: Scenario | E24: Total Cost | L24: Stack Composition
D25: Development Monthly | E25: =E5+E11 | L25: Eco dyno + Essential-0 Postgres
D26: Lean Production Monthly | E26: =E7+E14+E17 | L26: Standard-1X + Standard-0 + Bucketeer (no auto HA)
D27: RECOMMENDED Production Monthly | E27: =E7+E15+E17+E18 | L27: Standard-1X + Premium-0 HA + Bucketeer + ACM SSL
D28: Recommended Production Annual | E28: =(E7+E15+E17+E18)*12 | L28: Recommended monthly × 12
D29: Development Annual | E29: =(E5+E11)*12 | L29: Dev monthly × 12
D30: Lean Production Annual | E30: =(E7+E14+E17)*12 | L30: Lean monthly × 12
A32: Color legend:
A33: Green = Recommended production line item / total
A34: Blue = Lean production (cheaper, no automatic Postgres HA)
A35: Yellow = Development-only
A37: Pricing sources (as of Oct 2026): heroku.com/pricing, elements.heroku.com/addons/heroku-postgresql, elements.heroku.com/addons/bucketeer
A38: Saltbox app notes: Next.js + Postgres (DATABASE_URL); cookie sessions (no Redis); photos need object storage on Heroku.

Sheet Cardboard Sizes
A1: Length | B1: Width | C1: Height | D1: Cube | E1: Average Cube | F1: Mediun Cube | G1: Max Cube | H1: Min Cube
A2: 21.25 | B2: 21.25 | C2: 8 | D2: =PRODUCT(A2:C2) | E2: =AVERAGE(D2:D9) | F2: =MEDIAN(D2:D9) | G2: =MAX(D2:D9) | H2: =MIN(D2:D9)
A3: 23.75 | B3: 16 | C3: 11.5 | D3: =PRODUCT(A3:C3)
A4: 15.5 | B4: 15.5 | C4: 11.5 | D4: =PRODUCT(A4:C4)
A5: 18.25 | B5: 18.25 | C5: 18 | D5: =PRODUCT(A5:C5)
A6: 10.25 | B6: 10.25 | C6: 6 | D6: =PRODUCT(A6:C6)
A7: 11.25 | B7: 11.25 | C7: 7.5 | D7: =PRODUCT(A7:C7)
A8: 24 | B8: 24 | C8: 7.5 | D8: =PRODUCT(A8:C8)
A9: 12.5 | B9: 12.5 | C9: 12.5 | D9: =PRODUCT(A9:C9)

Sheet Hours
A1: Days Year | B1: Month Year | C1: Weeks Year | D1: Weeks / Month | E1: Avg Days / Month | F1: Days Week | G1: Hours Day | H1: Hours Week | I1: Work Days Week | J1: Work Hours Day | K1: Work Hours Week
A2: 365.2422 | B2: 12 | C2: =((52.14*3)+52.29)/4 | D2: =C2/B2 | E2: =(A2/C2)*D2 | F2: =A2/C2 | G2: 24 | H2: =F2*G2 | I2: 6 | J2: 8 | K2: =I2*J2
A4: NEON POSTGRES
A5: PLAN | B5: $ PER CU-HOUR | C5: HOURS 6 DAY WORK WEEK | D5: Hours Day | F5: Monthly CU-hours = [average CU size] × [number of hours the compute runs in the month] | G5: Monthly compute cost = [monthly CU-hours] × [CU-hour price]
A6: LAUNCH | B6: =0.106 | C6: =J2*6 | D6: 8
A7: SCALE | B7: =0.222
A9: HEROKU (flat monthly plans — NOT CU-hour billing)
A10: NOTE | B10: Heroku dynos and Classic/Essential Postgres are billed as monthly plan maximums (prorated by second). Do not apply Neon CU-hour formulas to Heroku production costs.
A12: SCENARIO | B12: MONTHLY $ | C12: ANNUAL $ | D12: COMPOSITION
A13: Development | B13: ='Cloud Expenses'!E25 | C13: ='Cloud Expenses'!E29 | D13: Eco $5 + Essential-0 $5
A14: Lean Production | B14: ='Cloud Expenses'!E26 | C14: ='Cloud Expenses'!E30 | D14: Standard-1X $25 + Standard-0 $50 + Bucketeer $5
A15: RECOMMENDED Production | B15: ='Cloud Expenses'!E27 | C15: ='Cloud Expenses'!E28 | D15: Standard-1X $25 + Premium-0 $200 + Bucketeer $5 + ACM $0
A17: Work-hour context (from row 2): warehouse ops use ~J2 work hours/day × I2 days/week — Heroku Standard/Premium stay always-on regardless of work hours (unlike Neon scale-to-zero).
